<?xml version="1.0"?>
<!-- Wheelie Bot URDF -->
<robot name="Wheelie Bot">


  <!-- Material Colours -->
  <material name="blue">
    <color rgba="0 0 0.8 1" />
  </material>

  <material name="black">
    <color rgba="0 0 0.0 1" />
  </material>

  <material name="white">
    <color rgba="1 1 1 1" />
  </material>

  <material name="red">
    <color rgba="1 0 0.0 1" />
  </material>

  <!-- Empty Botton Link -->
  <link name="base_footprint"></link>

  <link name="base_link">
    <visual>
      <geometry>
        <box size="1 1 0.1" />
      </geometry>
      <material name="blue" />
    </visual>
    <collision>
      <geometry>
        <box size="1 1 0.2" />
      </geometry>
    </collision>
    <inertial>
      <mass value="25" />
      <inertia ixx="0.4" ixy="0.0" ixz="0.0" iyy="0.4" iyz="0.0" izz="0.2" />
    </inertial>
  </link>

  <joint name="base_footprint_to_link" type="fixed">
    <parent link="base_footprint" />
    <child link="base_link" />
    <origin xyz="0 0 0.25" />
  </joint>

  <!-- Rear Right Wheel Setup -->
  <link name="rear_right_wheel">
    <visual>
      <geometry>
        <cylinder length="0.1" radius="0.25" />
      </geometry>
      <material name="black" />
    </visual>
    <collision>
      <geometry>
        <cylinder length="0.1" radius="0.25" />
      </geometry>
    </collision>
    <inertial>
      <mass value="1" />
      <inertia ixx="0.01" ixy="0.0" ixz="0.0" iyy="0.01" iyz="0.0" izz="0.01" />
    </inertial>
  </link>

  <joint name="rear_right_wheel_joint" type="continuous">
    <parent link="base_link" />
    <child link="rear_right_wheel" />
    <origin xyz="-0.4 -0.6 0" rpy="1.57075 0 0" />
    <axis xyz="0 0 -1" />
    <calibration rising="0.0" />
    <dynamics damping="0.0" friction="0.05" />
    <limit effort="30" velocity="10.0" />
    <safety_controller k_velocity="10" k_position="15" soft_lower_limit="-2.0" soft_upper_limit="0.5" />
  </joint>

  <gazebo reference="rear_right_wheel">
    <mu1 value="200.0" />
    <mu2 value="100.0" />
    <kp value="10000000.0" />
    <kd value="1.0" />
    <material>Gazebo/Grey</material>
  </gazebo>

  <transmission name="rear_right_wheel_trans">
    <type>transmission_interface/SimpleTransmission</type>
    <joint name="rear_right_wheel_joint">
      <hardwareInterface>VelocityJointInterface</hardwareInterface>
    </joint>
    <actuator name="rear_right_wheel_motor">
      <mechanicalReduction>1</mechanicalReduction>
      <!-- <hardwareInterface>EffortJointInterface</hardwareInterface> -->
    </actuator>
  </transmission>


  <!-- Rear Left Wheel Setup -->
  <link name="rear_left_wheel">
    <visual>
      <geometry>
        <cylinder length="0.1" radius="0.25" />
      </geometry>
      <material name="black" />
    </visual>
    <collision>
      <geometry>
        <cylinder length="0.1" radius="0.25" />
      </geometry>
    </collision>
    <inertial>
      <mass value="1" />
      <inertia ixx="0.01" ixy="0.0" ixz="0.0" iyy="0.01" iyz="0.0" izz="0.01" />
    </inertial>
  </link>

  <joint name="rear_left_wheel_joint" type="continuous">
    <parent link="base_link" />
    <child link="rear_left_wheel" />
    <origin xyz="-0.4 0.6 0" rpy="-1.57075 0 0" />
    <axis xyz="0 0 1" />
    <calibration rising="0.0" />
    <dynamics damping="0.0" friction="0.05" />
    <limit effort="30" velocity="10.0" />
    <safety_controller k_velocity="10" k_position="15" soft_lower_limit="-2.0" soft_upper_limit="0.5" />
  </joint>

  <gazebo reference="rear_left_wheel">
    <mu1 value="200.0" />
    <mu2 value="100.0" />
    <kp value="10000000.0" />
    <kd value="1.0" />
    <material>Gazebo/Grey</material>
  </gazebo>

  <transmission name="rear_left_wheel_trans">
    <type>transmission_interface/SimpleTransmission</type>
    <joint name="rear_left_wheel_joint">
      <hardwareInterface>VelocityJointInterface</hardwareInterface>
    </joint>
    <actuator name="rear_left_wheel_motor">
      <mechanicalReduction>1</mechanicalReduction>
      <!-- <hardwareInterface>EffortJointInterface</hardwareInterface> -->
    </actuator>
  </transmission>


  <!-- Front Caster Setup -->
  <link name="front_caster">
    <visual>
      <geometry>
        <box size="0.05 0.5 0.02" />
      </geometry>
      <material name="black" />
    </visual>
    <collision>
      <geometry>
        <box size="0.05 1.25 0.02" />
      </geometry>
    </collision>
    <inertial>
      <mass value="1" />
      <inertia ixx="0.2" ixy="0.0" ixz="0.0" iyy="0.2" iyz="0.0" izz="0.1" />
    </inertial>
  </link>

  <joint name="front_caster_joint" type="continuous">
    <parent link="base_link" />
    <child link="front_caster" />
    <origin xyz="0.4 0 -0.09" rpy="0 0 0" />
    <axis xyz="0 0 1" />
    <calibration rising="0.0" />
    <dynamics damping="0.0" friction="0.00" />
    <limit effort="30" velocity="1.0" lower="-2.2" upper="0.7" />
    <safety_controller k_velocity="10" k_position="15" soft_lower_limit="-2.0" soft_upper_limit="0.5" />
  </joint>


  <!-- Front Caster Wheel Setup -->
  <link name="front_caster_wheel">
    <visual>
      <geometry>
        <cylinder length="0.1" radius="0.065" />
      </geometry>
      <material name="white" />
    </visual>
    <collision>
      <geometry>
        <cylinder length="0.1" radius="0.065" />
      </geometry>
    </collision>
    <inertial>
      <mass value="0.5" />
      <inertia ixx="0.02" ixy="0.0" ixz="0.0" iyy="0.02" iyz="0.0" izz="0.01" />
    </inertial>
  </link>

  <joint name="front_caster_wheel_joint" type="continuous">
    <parent link="front_caster" />
    <child link="front_caster_wheel" />
    <origin xyz="0.0 -0 -0.095" rpy="1.57075 0 0" />
    <axis xyz="0 0 -1" />
    <calibration rising="0.0" />
    <dynamics damping="0.0" friction="0.05" />
    <limit effort="30" velocity="1.0" lower="-2.2" upper="0.7" />
    <safety_controller k_velocity="10" k_position="15" soft_lower_limit="-2.0" soft_upper_limit="0.5" />
  </joint>

  <gazebo reference="front_caster_wheel">
    <mu1 value="1" />
    <mu2 value="1" />
    <kp value="10000000.0" />
    <kd value="1.0" />
    <material>Gazebo/Grey</material>
  </gazebo>

  <!-- <transmission name="front_caster_wheel_trans">
    <type>transmission_interface/SimpleTransmission</type>
    <joint name="front_caster_joint">
      <hardwareInterface>EffortJointInterface </hardwareInterface>
    </joint>
  </transmission> -->


  <!--

    Implement

  -->

  <!-- Link Connector -->
  <link name="implement_connector">
    <visual>
      <origin xyz="-1 0 0" rpy="0 0 0" />
      <geometry>
        <box size="2 0.1 0.1" />
      </geometry>
      <material name="blue" />
    </visual>
    <collision>
      <origin xyz="-1 0 0" rpy="0 0 0" />
      <geometry>
        <box size="1 1 0.2" />
      </geometry>
    </collision>
    <inertial>
      <mass value="0.5" />
      <inertia ixx="0.01" ixy="0.0" ixz="0.0" iyy="0.05" iyz="0.0" izz="0.02" />
    </inertial>
  </link>

  <joint name="implement_connector_joint" type="revolute">
    <parent link="base_link" />
    <child link="implement_connector" />
    <origin xyz="-0.5 -0 0.25" rpy="0 0 0" />
    <calibration rising="0.0" />
    <dynamics damping="0.05" friction="0.4" />
    <limit effort="1000.0" lower="-1.4" upper="1.4" velocity="0.5" />
    <axis xyz="0 0 1" />
  </joint>


  <!-- Implement Base -->

  <link name="implement_base_platform">
    <visual>
      <origin xyz="0 0 0" rpy="0 0 0" />
      <geometry>
        <box size="0.5 1 0.1" />
      </geometry>
      <material name="blue" />
    </visual>
    <collision>
      <origin xyz="0 0 0" rpy="0 0 0" />
      <geometry>
        <box size="0.5 0.5 0.1" />
      </geometry>
    </collision>
    <inertial>
      <mass value="1" />
      <inertia ixx="0.1" ixy="0.0" ixz="0.0" iyy="0.05" iyz="0.0" izz="0.2" />
    </inertial>
  </link>

  <joint name="implement_connector_base_platform_joint" type="fixed">
    <parent link="implement_connector" />
    <child link="implement_base_platform" />
    <origin xyz="-2 -0 -0.25" rpy="0 0 0" />
  </joint>

  <!-- Implement Base Left Wheel -->
  <link name="implement_base_platform_left_wheel">
    <visual>
      <geometry>
        <cylinder length="0.1" radius="0.25" />
      </geometry>
      <material name="black" />
    </visual>
    <collision>
      <geometry>
        <cylinder length="0.1" radius="0.25" />
      </geometry>
    </collision>
    <inertial>
      <mass value="1" />
      <inertia ixx="0.01" ixy="0.0" ixz="0.0" iyy="0.01" iyz="0.0" izz="0.01" />
    </inertial>
  </link>

  <joint name="implement_base_platform_left_wheel_joint" type="continuous">
    <parent link="implement_base_platform" />
    <child link="implement_base_platform_left_wheel" />
    <origin xyz="0 0.6 0" rpy="-1.57075 0 0" />
    <axis xyz="0 0 1" />
    <calibration rising="0.0" />
    <dynamics damping="0.0" friction="0.05" />
    <limit effort="30" velocity="10.0" />
    <safety_controller k_velocity="10" k_position="15" soft_lower_limit="-2.0" soft_upper_limit="0.5" />
  </joint>

  <gazebo reference="implement_base_platform_left_wheel">
    <mu1 value="0.05" />
    <mu2 value="0.05" />
    <kp value="10000000.0" />
    <kd value="1.0" />
    <material>Gazebo/Grey</material>
  </gazebo>

  <!-- Implement Base Right Wheel -->
  <link name="implement_base_platform_right_wheel">
    <visual>
      <geometry>
        <cylinder length="0.1" radius="0.25" />
      </geometry>
      <material name="black" />
    </visual>
    <collision>
      <geometry>
        <cylinder length="0.1" radius="0.25" />
      </geometry>
    </collision>
    <inertial>
      <mass value="1" />
      <inertia ixx="0.01" ixy="0.0" ixz="0.0" iyy="0.01" iyz="0.0" izz="0.01" />
    </inertial>
  </link>

  <joint name="implement_base_platform_right_wheel_joint" type="continuous">
    <parent link="implement_base_platform" />
    <child link="implement_base_platform_right_wheel" />
    <origin xyz="0 -0.6 0" rpy="-1.57075 0 0" />
    <axis xyz="0 0 -1" />
    <calibration rising="0.0" />
    <dynamics damping="0.0" friction="0.05" />
    <limit effort="30" velocity="10.0" />
    <safety_controller k_velocity="10" k_position="15" soft_lower_limit="-2.0" soft_upper_limit="0.5" />
  </joint>

  <gazebo reference="implement_base_platform_right_wheel">
    <mu1 value="1" />
    <mu2 value="1" />
    <kp value="10000000.0" />
    <kd value="1.0" />
    <material>Gazebo/Grey</material>
  </gazebo>


  <!--

    Sensor Setup

  -->

  <!-- GPS Sensor -->
  <link name="gps_link">
    <visual>
      <geometry>
        <box size="0.1 0.1 0.1" />
      </geometry>
      <material name="red" />
    </visual>
    <collision>
      <geometry>
        <box size="0.1 0.1 0.1" />
      </geometry>
    </collision>
    <inertial>
      <mass value="0.00001" />
      <inertia ixx="0.0004" ixy="0.0" ixz="0.0" iyy="0.00004" iyz="0.0" izz="0.00002" />
    </inertial>
  </link>

  <joint name="gps_base_link_tf" type="fixed">
    <parent link="base_link" />
    <child link="gps_link" />
    <origin xyz="0 0 0.75" />
  </joint>

  <gazebo>
    <plugin name="gps_sim" filename="libhector_gazebo_ros_gps.so">
      <alwaysOn>1</alwaysOn>
      <updateRate>10.0</updateRate>
      <bodyName>gps_link</bodyName>
      <topicName>fix</topicName>
      <velocityTopicName>fix_velocity</velocityTopicName>
      <drift>0.0 0.0 0.0</drift>
      <referenceLatitude>49.9</referenceLatitude>
      <referenceLongitude>8.9</referenceLongitude>
      <status>2</status>
      <service>15</service>
      <gaussianNoise>0.1 0.1 0.1</gaussianNoise>
      <velocityDrift>0 0 0</velocityDrift>
      <velocityGaussianNoise>0.1 0.1 0.1</velocityGaussianNoise>
    </plugin>
  </gazebo>

  <!-- IMU Sensor -->
  <link name="imu_link">
    <visual>
      <geometry>
        <box size="0.1 0.1 0.1" />
      </geometry>
      <material name="red" />
    </visual>
    <collision>
      <geometry>
        <box size="0.1 0.1 0.1" />
      </geometry>
    </collision>
    <inertial>
      <mass value="0.00001" />
      <inertia ixx="0.0004" ixy="0.0" ixz="0.0" iyy="0.00004" iyz="0.0" izz="0.00002" />
    </inertial>
  </link>

  <joint name="imu_base_link_tf" type="fixed">
    <parent link="base_link" />
    <child link="imu_link" />
    <origin xyz="0 0 0.20" />
  </joint>


  <gazebo>
    <plugin name="imu_sim" filename="libhector_gazebo_ros_imu.so">
      <alwaysOn>1</alwaysOn>
      <updateRate>50.0</updateRate>
      <bodyName>imu_link</bodyName>
      <topicName>/imu/data</topicName>
    </plugin>
  </gazebo>

  <!-- Hokuyo Laser Sensor -->

  <link name="hokuyo_link">
    <visual>
      <geometry>
        <mesh filename="package://wheelie_bot/meshes/hokuyo.dae" />
      </geometry>
      <material name="red" />
    </visual>
    <collision>
      <geometry>
        <box size="0.01 0.01 0.01" />
      </geometry>
    </collision>
    <inertial>
      <mass value="0.00001" />
      <inertia ixx="0.0004" ixy="0.0" ixz="0.0" iyy="0.00004" iyz="0.0" izz="0.00002" />
    </inertial>
  </link>

  <joint name="laser_base_link_tf" type="fixed">
    <parent link="base_link" />
    <child link="hokuyo_link" />
    <origin xyz="0.4 0 0.45" />
  </joint>

  <gazebo reference="hokuyo_link">
    <sensor type="gpu_ray" name="head_hokuyo_sensor">
      <pose>0 0 0 0 0 0</pose>
      <visualize>false</visualize>
      <update_rate>10</update_rate>
      <ray>
        <scan>
          <horizontal>
            <samples>720</samples>
            <resolution>1</resolution>
            <min_angle>-1.570796</min_angle>
            <max_angle>1.570796</max_angle>
          </horizontal>
        </scan>
        <range>
          <min>0.10</min>
          <max>30.0</max>
          <resolution>0.01</resolution>
        </range>
        <noise>
          <type>gaussian</type>
          <!-- Noise parameters based on published spec for Hokuyo laser
               achieving "+-30mm" accuracy at range < 10m.  A mean of 0.0m and
               stddev of 0.01m will put 99.7% of samples within 0.03m of the true
               reading. -->
          <mean>0.0</mean>
          <stddev>0.01</stddev>
        </noise>
      </ray>
      <plugin name="gazebo_ros_head_hokuyo_controller" filename="libgazebo_ros_gpu_laser.so">
        <topicName>/scan</topicName>
        <frameName>hokuyo_link</frameName>
      </plugin>
    </sensor>
  </gazebo>


  <!-- Gazebo plugin for ROS Control -->
  <gazebo>
    <plugin name="gazebo_ros_control" filename="libgazebo_ros_control.so">
      <robotNamespace>/</robotNamespace>
    </plugin>
  </gazebo>

</robot>